I'm sorry, but an uncaught exception occurred.

While running game code:
  File "game/script.rpy", line 120, in script
    $ chapitre_actuel = chapitre_4_3_0
  File "game/script.rpy", line 120, in <module>
    $ chapitre_actuel = chapitre_4_3_0
NameError: name 'chapitre_4_3_0' is not defined

-- Full Traceback ------------------------------------------------------------

Full traceback:
  File "game/script.rpy", line 120, in script
    $ chapitre_actuel = chapitre_4_3_0
  File "C:\Users\a.riallot\Desktop\renpy-8.0.3-sdk\renpy\ast.py", line 1131, in execute
    renpy.python.py_exec_bytecode(self.code.bytecode, self.hide, store=self.store)
  File "C:\Users\a.riallot\Desktop\renpy-8.0.3-sdk\renpy\python.py", line 1061, in py_exec_bytecode
    exec(bytecode, globals, locals)
  File "game/script.rpy", line 120, in <module>
    $ chapitre_actuel = chapitre_4_3_0
NameError: name 'chapitre_4_3_0' is not defined

Windows-10-10.0.19044 AMD64
Ren'Py 8.0.3.22090809
WorkshopChapitre4 1.0
Tue Feb  7 12:55:14 2023
